Workbook

Sheet Overview
C2: Manchester United | Corporate finance & valuation
C3: FY2024–26 reported • FY2027–31 scenarios • valuation at 30 September 2026
C4: Case selected | E4: =CHOOSE(Assumptions!$E$5,"Base","Downside","Upside") -> Base
C7: Financial result | E7: 2027 | F7: 2028 | G7: 2029 | H7: 2030 | I7: 2031
C8: Revenue | E8: =Statements!E8 -> 750 | F8: =Statements!F8 -> 714.7 | G8: =Statements!G8 -> 728.715 | H8: =Statements!H8 -> 743.11845 | I8: =Statements!I8 -> 757.92136
C9: EBITDA before disposal gains | E9: =Statements!E11 -> 215 | F9: =Statements!F11 -> 177 | G9: =Statements!G11 -> 183.501 | H9: =Statements!H11 -> 185.48017 | I9: =Statements!I11 -> 182.85032
C10: Net income | E10: =Statements!E23 -> -20.075187 | F10: =Statements!F23 -> -38.065207 | G10: =Statements!G23 -> -0.83279506 | H10: =Statements!H23 -> 32.614492 | I10: =Statements!I23 -> 53.310518
C11: Cash after operations / investment | E11: =Statements!E31 -> -119.89098 | F11: =Statements!F31 -> -30.391152 | G11: =Statements!G31 -> 85.591264 | H11: =Statements!H31 -> 58.778507 | I11: =Statements!I31 -> 60.709948
C12: Peak revolver usage | E12: =Statements!E52 -> 245.50323 | F12: =Statements!F52 -> 265.22178 | G12: =Statements!G52 -> 256.63236 | H12: =Statements!H52 -> 183.18726 | I12: =Statements!I52 -> 130.30953
C13: Maximum cash reserve shortfall | E13: =Statements!E53 -> 0 | F13: =Statements!F53 -> 0 | G13: =Statements!G53 -> 0 | H13: =Statements!H53 -> 3.5527137e-15 | I13: =Statements!I53 -> 0
C14: PL actual green headroom | E14: ='PL bridge'!E18 -> 205.40098 | F14: ='PL bridge'!F18 -> 185.3073 | G14: ='PL bridge'!G18 -> 214.21561 | H14: ='PL bridge'!H18 -> 240.84173 | I14: ='PL bridge'!I18 -> 259.64989
C15: PL in-season green headroom | E15: ='PL bridge'!E26 -> 187.65098 | F15: ='PL bridge'!F26 -> 167.5573 | G15: ='PL bridge'!G26 -> 196.46561 | H15: ='PL bridge'!H26 -> 223.09173 | I15: ='PL bridge'!I26 -> 241.89989
C16: PL adjusted-equity headroom | E16: ='PL bridge'!E49 -> 218.4101 | F16: ='PL bridge'!F49 -> 122.90852 | G16: ='PL bridge'!G49 -> 115.96387 | H16: ='PL bridge'!H49 -> 212.00618 | I16: ='PL bridge'!I49 -> 311.82191
C17: UEFA SCR headroom (CY2026–30) | E17: ='UEFA bridge'!E18 -> 81.602629 | F17: ='UEFA bridge'!F18 -> 80.547075 | G17: ='UEFA bridge'!G18 -> 87.628468 | H17: ='UEFA bridge'!H18 -> 114.80613 | I17: ='UEFA bridge'!I18 -> 136.28487
C18: UEFA earnings (licences 2026/27–30/31) | E18: ='UEFA bridge'!E27 -> -60.773 | F18: ='UEFA bridge'!F27 -> 58.83209 | G18: ='UEFA bridge'!G27 -> 14.130883 | H18: ='UEFA bridge'!H27 -> 61.283088 | I18: ='UEFA bridge'!I27 -> 106.01649
C21: Minimum modelled headroom across the horizon
C22: Cash reserve / funding | E22: =MIN('Debt cash'!E47:BL47) -> 134.77822
C23: EBITDA covenant | E23: =MIN('Debt cash'!E38:BL38) -> 52
C24: PL green cost limit | E24: =MIN('PL bridge'!E18:I18,'PL bridge'!E26:I26) -> 167.5573
C25: PL working capital | E25: =MIN('PL bridge'!E37:I37) -> 147.02822
C26: PL stressed liquidity | E26: =MIN('PL bridge'!E42:H42) -> 399.56387
C27: PL adjusted equity | E27: =MIN('PL bridge'!E49:I49) -> 115.96387
C28: UEFA squad-cost limit | E28: =MIN(IF('UEFA bridge'!E19=1,'UEFA bridge'!E18,1000000),IF('UEFA bridge'!F19=1,'UEFA bridge'!F18,1000000),IF('UEFA bridge'!G19=1,'UEFA bridge'!G18,1000000),IF('UEFA bridge'!H19=1,'UEFA bridge'!H18,1000000),IF('UEFA bridge'!I19=1,'UEFA bridge'!I18,1000000),IF(Assumptions!I303=1,'UEFA bridge'!E38,1000000)) -> 80.547075
C29: UEFA football earnings | E29: =MIN(IF('UEFA bridge'!E19=1,'UEFA bridge'!E27,1000000),IF('UEFA bridge'!F19=1,'UEFA bridge'!F27,1000000),IF('UEFA bridge'!G19=1,'UEFA bridge'!G27,1000000),IF('UEFA bridge'!H19=1,'UEFA bridge'!H27,1000000),IF('UEFA bridge'!I19=1,'UEFA bridge'!I27,1000000),IF(Assumptions!I303=1,'UEFA bridge'!E37,1000000)) -> -60.773
C30: UEFA December equity proxy | E30: =MIN(IF('UEFA bridge'!E19=1,'UEFA bridge'!E33,1000000),IF('UEFA bridge'!F19=1,'UEFA bridge'!F33,1000000),IF('UEFA bridge'!G19=1,'UEFA bridge'!G33,1000000),IF('UEFA bridge'!H19=1,'UEFA bridge'!H33,1000000),IF('UEFA bridge'!I19=1,'UEFA bridge'!I33,1000000)) -> 107.32723
C32: Tightest headroom screen | E32: =MIN(E22:E30) -> -60.773
C33: Most restrictive screen | E33: =INDEX(C22:C30,MATCH(E32,E22:E30,0)) -> UEFA football earnings
C34: Proxy feasibility | E34: =IF(E32>=0,"Within modelled screens","Outside modelled screens") -> Outside modelled screens
C36: Refinancing assumption | E36: =IF(Capacity!E8=1,"Uncommitted rollover assumed","Contractual repayment required") -> Uncommitted rollover assumed
C38: Results are public-data scenario proxies, not an internal budget or certified compliance.
C39: FY2032 SSR and full CY2031 UEFA require forecasts beyond this five-year model.
C40: Negative cash denotes unmet funding; the model does not assume payments can still settle.
C42: Prospective headroom excluding inherited FE | E42: =MIN(E22:E28,E30,IF('UEFA bridge'!F19=1,'UEFA bridge'!F27,1000000),IF('UEFA bridge'!G19=1,'UEFA bridge'!G27,1000000),IF('UEFA bridge'!H19=1,'UEFA bridge'!H27,1000000),IF('UEFA bridge'!I19=1,'UEFA bridge'!I27,1000000),IF(Assumptions!I303=1,'UEFA bridge'!E37,1000000)) -> 14.130883
C43: Historical FE extra eligible adjustments needed | E43: =MAX(0,-'UEFA bridge'!E27) -> 60.773
C44: Required historical average adjustment (£m/year) | E44: =MAX(0,-'UEFA bridge'!E22-'UEFA bridge'!E26)/3 -> 55.257667
C46: Prospective screen assumes the historical football-earnings return is reconciled separately.
C49: Valuation and cash generation • active operating case
C50: DCF enterprise value | E50: =Valuation!E63 -> 424.29787
C51: DCF equity value (limited liability) | E51: =Valuation!E71 -> 0
C52: Implied price / diluted economic share, USD | E52: =Valuation!E72 -> 0
...

Sheet Capacity
C2: Capacity
C3: £m unless stated. Evidence cut-off: 8 October 2026.
C4: Case selected | E4: =CHOOSE(Assumptions!$E$5,"Base","Downside","Upside") -> Base
C6: FY2027 incremental transfer face cost | E6: 0
C7: FY2027 incremental annual all-in wages | E7: 0
C8: Refinance maturities: 0 no / 1 assumed rollover | E8: 1
C9: Squad payroll share override (−1 = scenario) | E9: -1
C10: Squad market value override (−1 = scenario) | E10: -1
C11: Sale proceeds multiplier | E11: 1
C12: Floating-rate shift | E12: 0
C14: Live matrix: minimum headroom (£m), all modelled screens
C15: Columns = incremental face fees; rows = annual employer cost. FY2027 January start.
E17: =Overview!E32 -> -60.773 | F17: 0 | G17: 25 | H17: 50 | I17: 100 | J17: 150
E18: 0 | F18: -60.773 | G18: -60.773 | H18: -60.773 | I18: -60.773 | J18: -60.773
E19: 5 | F19: -60.773 | G19: -60.773 | H19: -60.773 | I19: -60.773 | J19: -60.773
E20: 10 | F20: -60.773 | G20: -60.773 | H20: -60.773 | I20: -60.773 | J20: -60.773
E21: 20 | F21: -60.773 | G21: -60.773 | H21: -60.773 | I21: -60.773 | J21: -86.965282
E22: 30 | F22: -60.773 | G22: -60.773 | H22: -60.773 | I22: -82.705495 | J22: -113.93675
C24: A non-negative cell passes the modelled proxy screens only. It is not certification.
C25: If the zero/zero cell is negative, no incremental package is feasible under these inputs.
C28: Base conditional frontier - saved snapshot
C29: Conditional: assumed rollover; unresolved historical UEFA earnings screen excluded.
F30: 0 | G30: 25 | H30: 50 | I30: 100 | J30: 150
E31: 0 | F31: 14.130883 | G31: 4.9119191 | H31: -4.3019372 | I31: -22.716584 | J31: -41.116797
E32: 5 | F32: 6.2753888 | G32: -2.9435748 | H32: -12.157431 | I32: -30.572078 | J32: -48.972291
E33: 10 | F33: -1.5801052 | G33: -10.799069 | H33: -20.012925 | I33: -38.427572 | J33: -59.913037
E34: 20 | F34: -17.291093 | G34: -26.510057 | H34: -35.723913 | I34: -55.638952 | J34: -86.965282
E35: 30 | F35: -33.002081 | G35: -42.221045 | H35: -51.434901 | I35: -82.705495 | J35: -113.93675
C38: Downside conditional frontier - saved snapshot
C39: Conditional: assumed rollover; unresolved historical UEFA earnings screen excluded.
F40: 0 | G40: 25 | H40: 50 | I40: 100 | J40: 150
E41: 0 | F41: -758.65746 | G41: -784.14225 | H41: -809.35598 | I41: -859.41666 | J41: -909.41666
E42: 5 | F42: -778.71645 | G42: -804.18416 | H42: -829.37265 | I42: -879.41666 | J42: -929.41666
E43: 10 | F43: -798.77544 | G43: -824.22607 | H43: -849.38931 | I43: -899.41666 | J43: -949.41666
E44: 20 | F44: -838.89341 | G44: -864.30233 | H44: -889.41666 | I44: -939.41666 | J44: -989.41666
E45: 30 | F45: -879.01138 | G45: -904.35598 | H45: -929.41666 | I45: -979.41666 | J45: -1029.4167
C48: Upside conditional frontier - saved snapshot
C49: Conditional: assumed rollover; unresolved historical UEFA earnings screen excluded.
F50: 0 | G50: 25 | H50: 50 | I50: 100 | J50: 150
E51: 0 | F51: 92.123083 | G51: 92.123083 | H51: 92.123083 | I51: 92.123083 | J51: 92.123083
...

Sheet Assumptions
C2: Assumptions
C3: £m unless stated. Evidence cut-off: 8 October 2026.
C4: Case selected | E4: =CHOOSE(Assumptions!$E$5,"Base","Downside","Upside") -> Base
C5: Case number: 1 Base / 2 Downside / 3 Upside | E5: 1
C7: Driver / case | E7: 2027 | F7: 2028 | G7: 2029 | H7: 2030 | I7: 2031 | K7: F/E/A | L7: Basis and rationale
C8: Ordinary commercial revenue — active | E8: =CHOOSE($E$5,E9,E10,E11) -> 350 | F8: =CHOOSE($E$5,F9,F10,F11) -> 360.5 | G8: =CHOOSE($E$5,G9,G10,G11) -> 371.315 | H8: =CHOOSE($E$5,H9,H10,H11) -> 382.45445 | I8: =CHOOSE($E$5,I9,I10,I11) -> 393.92808 | K8: A | L8: A. Analyst scenario, 8 Oct 2026. Low confidence.
C9: Base | E9: 350 | F9: 360.5 | G9: 371.315 | H9: 382.45445 | I9: 393.92808
C10: Downside | E10: 335 | F10: 335 | G10: 335 | H10: 335 | I10: 335
C11: Upside | E11: 360 | F11: 378 | G11: 396.9 | H11: 416.745 | I11: 437.58225
C13: Domestic and other broadcast — active | E13: =CHOOSE($E$5,E14,E15,E16) -> 160 | F13: =CHOOSE($E$5,F14,F15,F16) -> 160 | G13: =CHOOSE($E$5,G14,G15,G16) -> 160 | H13: =CHOOSE($E$5,H14,H15,H16) -> 160 | I13: =CHOOSE($E$5,I14,I15,I16) -> 160 | K13: A | L13: A. Analyst scenario, 8 Oct 2026. Low confidence.
C14: Base | E14: 160 | F14: 160 | G14: 160 | H14: 160 | I14: 160
C15: Downside | E15: 155 | F15: 150.35 | G15: 145.8395 | H15: 141.46431 | I15: 137.22039
C16: Upside | E16: 165 | F16: 169.95 | G16: 175.0485 | H16: 180.30095 | I16: 185.70998
C18: European broadcast — active | E18: =CHOOSE($E$5,E19,E20,E21) -> 65 | F18: =CHOOSE($E$5,F19,F20,F21) -> 35 | G18: =CHOOSE($E$5,G19,G20,G21) -> 35 | H18: =CHOOSE($E$5,H19,H20,H21) -> 35 | I18: =CHOOSE($E$5,I19,I20,I21) -> 35 | K18: A | L18: A. Analyst scenario, 8 Oct 2026. Low confidence.
C19: Base | E19: 65 | F19: 35 | G19: 35 | H19: 35 | I19: 35
C20: Downside | E20: 60 | F20: 5 | G20: 5 | H20: 5 | I20: 5
C21: Upside | E21: 70 | F21: 80 | G21: 80 | H21: 80 | I21: 80
C23: Matchday — active | E23: =CHOOSE($E$5,E24,E25,E26) -> 175 | F23: =CHOOSE($E$5,F24,F25,F26) -> 160 | G23: =CHOOSE($E$5,G24,G25,G26) -> 163.2 | H23: =CHOOSE($E$5,H24,H25,H26) -> 166.464 | I23: =CHOOSE($E$5,I24,I25,I26) -> 169.79328 | K23: A | L23: A. Analyst scenario, 8 Oct 2026. Low confidence.
C24: Base | E24: 175 | F24: 160 | G24: 163.2 | H24: 166.464 | I24: 169.79328
C25: Downside | E25: 170 | F25: 145 | G25: 145 | H25: 145 | I25: 145
C26: Upside | E26: 185 | F26: 185 | G26: 190.55 | H26: 196.2665 | I26: 202.15449
C28: Additional CL misses versus opening contract estimate — active | E28: =CHOOSE($E$5,E29,E30,E31) -> 0 | F28: =CHOOSE($E$5,F29,F30,F31) -> 1 | G28: =CHOOSE($E$5,G29,G30,G31) -> 0 | H28: =CHOOSE($E$5,H29,H30,H31) -> 0 | I28: =CHOOSE($E$5,I29,I30,I31) -> 0 | K28: A | L28: A. Changes versus undisclosed opening adidas estimate. £0.8m annual recognition per additional miss. Not the full contractual £10m deduction.
C29: Base | E29: 0 | F29: 1 | G29: 0 | H29: 0 | I29: 0
C30: Downside | E30: 0 | F30: 1 | G30: 1 | H30: 1 | I30: 1
C31: Upside | E31: 0 | F31: 0 | G31: 0 | H31: 0 | I31: 0
C33: Adidas incremental cash deduction — active | E33: =CHOOSE($E$5,E34,E35,E36) -> 0 | F33: =CHOOSE($E$5,F34,F35,F36) -> 10 | G33: =CHOOSE($E$5,G34,G35,G36) -> 0 | H33: =CHOOSE($E$5,H34,H35,H36) -> 0 | I33: =CHOOSE($E$5,I34,I35,I36) -> 0 | K33: A | L33: A. Assumed same-year cash settlement of incremental missed seasons only. Difference from recognised revenue rolls through contract asset.
C34: Base | E34: 0 | F34: 10 | G34: 0 | H34: 0 | I34: 0
C35: Downside | E35: 0 | F35: 10 | G35: 10 | H35: 10 | I35: 10
C36: Upside | E36: 0 | F36: 0 | G36: 0 | H36: 0 | I36: 0
C38: Inherited group payroll before leavers — active | E38: =CHOOSE($E$5,E39,E40,E41) -> 350 | F38: =CHOOSE($E$5,F39,F40,F41) -> 350 | G38: =CHOOSE($E$5,G39,G40,G41) -> 350 | H38: =CHOOSE($E$5,H39,H40,H41) -> 350 | I38: =CHOOSE($E$5,I39,I40,I41) -> 350 | K38: A | L38: A. FY2027 envelope includes known summer transactions. Future retained payroll separately inflates and removes leavers.
C39: Base | E39: 350 | F39: 350 | G39: 350 | H39: 350 | I39: 350
C40: Downside | E40: 365 | F40: 365 | G40: 365 | H40: 365 | I40: 365
C41: Upside | E41: 365 | F41: 365 | G41: 365 | H41: 365 | I41: 365
C43: Retained payroll inflation — active | E43: =CHOOSE($E$5,E44,E45,E46) -> 0 | F43: =CHOOSE($E$5,F44,F45,F46) -> 0.02 | G43: =CHOOSE($E$5,G44,G45,G46) -> 0.02 | H43: =CHOOSE($E$5,H44,H45,H46) -> 0.02 | I43: =CHOOSE($E$5,I44,I45,I46) -> 0.02 | K43: A | L43: A. Analyst scenario, 8 Oct 2026. Low confidence.
C44: Base | E44: 0 | F44: 0.02 | G44: 0.02 | H44: 0.02 | I44: 0.02
C45: Downside | E45: 0 | F45: 0.03 | G45: 0.03 | H45: 0.03 | I45: 0.03
C46: Upside | E46: 0 | F46: 0.03 | G46: 0.03 | H46: 0.03 | I46: 0.03
C48: Relevant squad share — active | E48: =CHOOSE($E$5,E49,E50,E51) -> 0.75 | F48: =CHOOSE($E$5,F49,F50,F51) -> 0.75 | G48: =CHOOSE($E$5,G49,G50,G51) -> 0.75 | H48: =CHOOSE($E$5,H49,H50,H51) -> 0.75 | I48: =CHOOSE($E$5,I49,I50,I51) -> 0.75 | K48: A | L48: A. Identification range 70–85%; broader sensitivity 65–90%. Includes relevant professionals and coach.
C49: Base | E49: 0.75 | F49: 0.75 | G49: 0.75 | H49: 0.75 | I49: 0.75
C50: Downside | E50: 0.85 | F50: 0.85 | G50: 0.85 | H50: 0.85 | I50: 0.85
...

Sheet Statements
C2: Statements
C3: £m unless stated. Evidence cut-off: 8 October 2026.
C4: Case selected | E4: =CHOOSE(Assumptions!$E$5,"Base","Downside","Upside") -> Base
C7: Fiscal year | E7: 2027 | F7: 2028 | G7: 2029 | H7: 2030 | I7: 2031
C8: Revenue | E8: =SUM('Revenue costs'!E14:P14) -> 750 | F8: =SUM('Revenue costs'!Q14:AB14) -> 714.7 | G8: =SUM('Revenue costs'!AC14:AN14) -> 728.715 | H8: =SUM('Revenue costs'!AO14:AZ14) -> 743.11845 | I8: =SUM('Revenue costs'!BA14:BL14) -> 757.92136
C9: Employee costs | E9: =SUM('Revenue costs'!E19:P19) -> 350 | F9: =SUM('Revenue costs'!Q19:AB19) -> 349 | G9: =SUM('Revenue costs'!AC19:AN19) -> 352.74 | H9: =SUM('Revenue costs'!AO19:AZ19) -> 361.3148 | I9: =SUM('Revenue costs'!BA19:BL19) -> 374.8211
C10: Other operating costs | E10: =SUM('Revenue costs'!E21:P21) -> 185 | F10: =SUM('Revenue costs'!Q21:AB21) -> 188.7 | G10: =SUM('Revenue costs'!AC21:AN21) -> 192.474 | H10: =SUM('Revenue costs'!AO21:AZ21) -> 196.32348 | I10: =SUM('Revenue costs'!BA21:BL21) -> 200.24995
C11: EBITDA before disposal gains | E11: =SUM('Revenue costs'!E22:P22) -> 215 | F11: =SUM('Revenue costs'!Q22:AB22) -> 177 | G11: =SUM('Revenue costs'!AC22:AN22) -> 183.501 | H11: =SUM('Revenue costs'!AO22:AZ22) -> 185.48017 | I11: =SUM('Revenue costs'!BA22:BL22) -> 182.85032
C12: Registration amortisation | E12: =SUM(Registrations!E89:P89) -> 183.95475 | F12: =SUM(Registrations!Q89:AB89) -> 167.57381 | G12: =SUM(Registrations!AC89:AN89) -> 141.0809 | H12: =SUM(Registrations!AO89:AZ89) -> 115.34468 | I12: =SUM(Registrations!BA89:BL89) -> 95.989274
C13: Tangible depreciation | E13: =SUM('Revenue costs'!E24:P24) -> 22 | F13: =SUM('Revenue costs'!Q24:AB24) -> 22 | G13: =SUM('Revenue costs'!AC24:AN24) -> 22 | H13: =SUM('Revenue costs'!AO24:AZ24) -> 22 | I13: =SUM('Revenue costs'!BA24:BL24) -> 22
C14: Other intangible amortisation | E14: =SUM('Revenue costs'!E25:P25) -> 3.4 | F14: =SUM('Revenue costs'!Q25:AB25) -> 3.4 | G14: =SUM('Revenue costs'!AC25:AN25) -> 3.4 | H14: =SUM('Revenue costs'!AO25:AZ25) -> 3.4 | I14: =SUM('Revenue costs'!BA25:BL25) -> 3.4
C15: Disposal gain / loss | E15: =SUM(Transfers!E25:P25) -> 40.632524 | F15: =SUM(Transfers!Q25:AB25) -> 33.849206 | G15: =SUM(Transfers!AC25:AN25) -> 33.849206 | H15: =SUM(Transfers!AO25:AZ25) -> 33.849206 | I15: =SUM(Transfers!BA25:BL25) -> 33.849206
C16: Operating profit | E16: =E11-E12-E13-E14+E15 -> 46.277773 | F16: =F11-F12-F13-F14+F15 -> 17.875401 | G16: =G11-G12-G13-G14+G15 -> 50.869305 | H16: =H11-H12-H13-H14+H15 -> 78.584699 | I16: =I11-I12-I13-I14+I15 -> 95.31025
C17: Accrued financial interest expense | E17: =SUM('Debt cash'!E22:P22)-SUM('Debt cash'!E57:P57)+SUM('Debt cash'!E48:P48)-SUM('Debt cash'!E49:P49) -> 43.613583 | F17: =SUM('Debt cash'!Q22:AB22)-SUM('Debt cash'!Q57:AB57)+SUM('Debt cash'!Q48:AB48)-SUM('Debt cash'!Q49:AB49) -> 45.790409 | G17: =SUM('Debt cash'!AC22:AN22)-SUM('Debt cash'!AC57:AN57)+SUM('Debt cash'!AC48:AN48)-SUM('Debt cash'!AC49:AN49) -> 44.253325 | H17: =SUM('Debt cash'!AO22:AZ22)-SUM('Debt cash'!AO57:AZ57)+SUM('Debt cash'!AO48:AZ48)-SUM('Debt cash'!AO49:AZ49) -> 39.828442 | I17: =SUM('Debt cash'!BA22:BL22)-SUM('Debt cash'!BA57:BL57)+SUM('Debt cash'!BA48:BL48)-SUM('Debt cash'!BA49:BL49) -> 35.911469
C18: Transfer net discount unwind | E18: =SUM(Transfers!E31:P31)-SUM(Transfers!E35:P35) -> 13.727933 | F18: =SUM(Transfers!Q31:AB31)-SUM(Transfers!Q35:AB35) -> 7.8757993 | G18: =SUM(Transfers!AC31:AN31)-SUM(Transfers!AC35:AN35) -> 5.174375 | H18: =SUM(Transfers!AO31:AZ31)-SUM(Transfers!AO35:AZ35) -> 3.8673646 | I18: =SUM(Transfers!BA31:BL31)-SUM(Transfers!BA35:BL35) -> 1.8973111
C19: Debt FX loss / gain | E19: =SUM('Debt cash'!E19:P19) -> -1.2192331 | F19: =SUM('Debt cash'!Q19:AB19) -> 0 | G19: =SUM('Debt cash'!AC19:AN19) -> 0 | H19: =SUM('Debt cash'!AO19:AZ19) -> 0 | I19: =SUM('Debt cash'!BA19:BL19) -> 0
C20: Debt cost amortisation | E20: =SUM('Debt cash'!E23:P23) -> 1.2744 | F20: =SUM('Debt cash'!Q23:AB23) -> 1.2744 | G20: =SUM('Debt cash'!AC23:AN23) -> 1.2744 | H20: =SUM('Debt cash'!AO23:AZ23) -> 1.2744 | I20: =SUM('Debt cash'!BA23:BL23) -> 1.2744
C21: Profit before tax | E21: =E16-SUM(E17:E20) -> -11.11891 | F21: =F16-SUM(F17:F20) -> -37.065207 | G21: =G16-SUM(G17:G20) -> 0.16720494 | H21: =H16-SUM(H17:H20) -> 33.614492 | I21: =I16-SUM(I17:I20) -> 56.22707
C22: Tax | E22: =SUM('Debt cash'!E10:P10) -> 8.9562772 | F22: =SUM('Debt cash'!Q10:AB10) -> 1 | G22: =SUM('Debt cash'!AC10:AN10) -> 1 | H22: =SUM('Debt cash'!AO10:AZ10) -> 1 | I22: =SUM('Debt cash'!BA10:BL10) -> 2.9165519
C23: Net income | E23: =SUM('Debt cash'!E40:P40) -> -20.075187 | F23: =SUM('Debt cash'!Q40:AB40) -> -38.065207 | G23: =SUM('Debt cash'!AC40:AN40) -> -0.83279506 | H23: =SUM('Debt cash'!AO40:AZ40) -> 32.614492 | I23: =SUM('Debt cash'!BA40:BL40) -> 53.310518
C26: Cash from operations before interest/tax | E26: =SUM('Debt cash'!E9:P9) -> 207.438 | F26: =SUM('Debt cash'!Q9:AB9) -> 167.8 | G26: =SUM('Debt cash'!AC9:AN9) -> 184.301 | H26: =SUM('Debt cash'!AO9:AZ9) -> 186.28017 | I26: =SUM('Debt cash'!BA9:BL9) -> 183.65032
C27: Operating cash after interest/tax | E27: =E26-SUM('Debt cash'!E22:P22)-E22 -> 153.46814 | F27: =F26-SUM('Debt cash'!Q22:AB22)-F22 -> 121.00959 | G27: =G26-SUM('Debt cash'!AC22:AN22)-G22 -> 139.04767 | H27: =H26-SUM('Debt cash'!AO22:AZ22)-H22 -> 145.45173 | I27: =I26-SUM('Debt cash'!BA22:BL22)-I22 -> 144.8223
C28: Acquisition cash | E28: =SUM(Transfers!E16:P16) -> 306.61404 | F28: =SUM(Transfers!Q16:AB16) -> 180.08643 | G28: =SUM(Transfers!AC16:AN16) -> 95.296384 | H28: =SUM(Transfers!AO16:AZ16) -> 108.27322 | I28: =SUM(Transfers!BA16:BL16) -> 105.71235
C29: Disposal receipts | E29: =SUM(Transfers!E28:P28) -> 61.65492 | F29: =SUM(Transfers!Q28:AB28) -> 57.085688 | G29: =SUM(Transfers!AC28:AN28) -> 70.239973 | H29: =SUM(Transfers!AO28:AZ28) -> 50 | I29: =SUM(Transfers!BA28:BL28) -> 50
C30: Tangible and other intangible capex | E30: =SUM('Debt cash'!E13:P13) -> 28.4 | F30: =SUM('Debt cash'!Q13:AB13) -> 28.4 | G30: =SUM('Debt cash'!AC13:AN13) -> 28.4 | H30: =SUM('Debt cash'!AO13:AZ13) -> 28.4 | I30: =SUM('Debt cash'!BA13:BL13) -> 28.4
C31: Cash after operating and investing | E31: =E27-E28+E29-E30 -> -119.89098 | F31: =F27-F28+F29-F30 -> -30.391152 | G31: =G27-G28+G29-G30 -> 85.591264 | H31: =H27-H28+H29-H30 -> 58.778507 | I31: =I27-I28+I29-I30 -> 60.709948
C32: Lease principal | E32: =SUM('Debt cash'!E14:P14) -> 1.2 | F32: =SUM('Debt cash'!Q14:AB14) -> 1.2 | G32: =SUM('Debt cash'!AC14:AN14) -> 0.87 | H32: =SUM('Debt cash'!AO14:AZ14) -> 0 | I32: =SUM('Debt cash'!BA14:BL14) -> 0
C33: Mandatory debt repayment | E33: =SUM('Debt cash'!E25:P25) -> 0 | F33: =SUM('Debt cash'!Q25:AB25) -> 0 | G33: =SUM('Debt cash'!AC25:AN25) -> 0 | H33: =SUM('Debt cash'!AO25:AZ25) -> 115.99294 | I33: =SUM('Debt cash'!BA25:BL25) -> 582.70677
C34: Assumed refinancing | E34: =SUM('Debt cash'!E26:P26) -> 0 | F34: =SUM('Debt cash'!Q26:AB26) -> 0 | G34: =SUM('Debt cash'!AC26:AN26) -> 0 | H34: =SUM('Debt cash'!AO26:AZ26) -> 115.99294 | I34: =SUM('Debt cash'!BA26:BL26) -> 582.70677
C35: Net revolver draw / (repayment) | E35: =SUM('Debt cash'!E30:P30)-SUM('Debt cash'!E31:P31)+SUM('Debt cash'!E51:P51) -> 78.844979 | F35: =SUM('Debt cash'!Q30:AB30)-SUM('Debt cash'!Q31:AB31)+SUM('Debt cash'!Q51:AB51) -> 31.591152 | G35: =SUM('Debt cash'!AC30:AN30)-SUM('Debt cash'!AC31:AN31)+SUM('Debt cash'!AC51:AN51) -> -84.721264 | H35: =SUM('Debt cash'!AO30:AZ30)-SUM('Debt cash'!AO31:AZ31)+SUM('Debt cash'!AO51:AZ51) -> -58.778507 | I35: =SUM('Debt cash'!BA30:BL30)-SUM('Debt cash'!BA31:BL31)+SUM('Debt cash'!BA51:BL51) -> -60.709948
C36: Closing cash | E36: ='Debt cash'!P33 -> 25 | F36: ='Debt cash'!AB33 -> 25 | G36: ='Debt cash'!AN33 -> 25 | H36: ='Debt cash'!AZ33 -> 25 | I36: ='Debt cash'!BL33 -> 25
C39: Registration NBV | E39: =Registrations!P92 -> 445.01703 | F39: =Registrations!AB92 -> 325.14666 | G39: =Registrations!AN92 -> 231.76919 | H39: =Registrations!AZ92 -> 164.12795 | I39: =Registrations!BL92 -> 115.84211
C40: Transfer receivables | E40: =Transfers!P36 -> 59.653769 | F40: =Transfers!AB36 -> 53.932397 | G40: =Transfers!AN36 -> 34.244211 | H40: =Transfers!AZ36 -> 34.244211 | I40: =Transfers!BL36 -> 34.244211
C41: Other assets | E41: ='Debt cash'!P43 -> 964.428 | F41: ='Debt cash'!AB43 -> 976.628 | G41: ='Debt cash'!AN43 -> 978.828 | H41: ='Debt cash'!AZ43 -> 981.028 | I41: ='Debt cash'!BL43 -> 983.228
C42: Total assets | E42: ='Debt cash'!P45 -> 1494.0988 | F42: ='Debt cash'!AB45 -> 1380.7071 | G42: ='Debt cash'!AN45 -> 1269.8414 | H42: ='Debt cash'!AZ45 -> 1204.4002 | I42: ='Debt cash'!BL45 -> 1158.3143
C44: Borrowings | E44: ='Debt cash'!P36 -> 766.45415 | F44: ='Debt cash'!AB36 -> 799.3197 | G44: ='Debt cash'!AN36 -> 715.87283 | H44: ='Debt cash'!AZ36 -> 658.36873 | I44: ='Debt cash'!BL36 -> 598.93318
C45: Transfer payables | E45: =Transfers!P32 -> 271.56784 | F45: =Transfers!AB32 -> 164.57575 | G45: =Transfers!AN32 -> 138.85976 | H45: =Transfers!AZ32 -> 98.30813 | I45: =Transfers!BL32 -> 58.34732
C46: Lease liabilities | E46: ='Debt cash'!P41 -> 2.07 | F46: ='Debt cash'!AB41 -> 0.87 | G46: ='Debt cash'!AN41 -> 0 | H46: ='Debt cash'!AZ41 -> 0 | I46: ='Debt cash'!BL41 -> 0
C47: Other liabilities | E47: ='Debt cash'!P44 -> 323.719 | F47: ='Debt cash'!AB44 -> 323.719 | G47: ='Debt cash'!AN44 -> 323.719 | H47: ='Debt cash'!AZ44 -> 323.719 | I47: ='Debt cash'!BL44 -> 323.719
C48: Total liabilities | E48: ='Debt cash'!P46 -> 1363.811 | F48: ='Debt cash'!AB46 -> 1288.4845 | G48: ='Debt cash'!AN46 -> 1178.4516 | H48: ='Debt cash'!AZ46 -> 1080.3959 | I48: ='Debt cash'!BL46 -> 980.9995
...

Sheet Revenue costs
C2: Revenue costs
C3: £m unless stated. Evidence cut-off: 8 October 2026.
C4: Case selected | E4: =CHOOSE(Assumptions!$E$5,"Base","Downside","Upside") -> Base
C7: Month | E7: 46204 | F7: 46235 | G7: 46266 | H7: 46296 | I7: 46327 | J7: 46357 | K7: 46388 | L7: 46419 | M7: 46447 | N7: 46478 | O7: 46508 | P7: 46539 | Q7: 46569 | R7: 46600 | S7: 46631 | T7: 46661 | U7: 46692 | V7: 46722 | W7: 46753 | X7: 46784 | Y7: 46813 | Z7: 46844 | AA7: 46874 | AB7: 46905 | AC7: 46935 | AD7: 46966 | AE7: 46997 | AF7: 47027 | AG7: 47058 | AH7: 47088 | AI7: 47119 | AJ7: 47150 | AK7: 47178 | AL7: 47209 | AM7: 47239 | AN7: 47270 | AO7: 47300 | AP7: 47331 | AQ7: 47362 | AR7: 47392 | AS7: 47423 | AT7: 47453 | AU7: 47484 | AV7: 47515 | AW7: 47543 | AX7: 47574 | AY7: 47604 | AZ7: 47635 | BA7: 47665 | BB7: 47696 | BC7: 47727 | BD7: 47757 | BE7: 47788 | BF7: 47818 | BG7: 47849 | BH7: 47880 | BI7: 47908 | BJ7: 47939 | BK7: 47969 | BL7: 48000
C8: Ordinary commercial revenue | E8: =Assumptions!E8/12 -> 29.166667 | F8: =Assumptions!E8/12 -> 29.166667 | G8: =Assumptions!E8/12 -> 29.166667 | H8: =Assumptions!E8/12 -> 29.166667 | I8: =Assumptions!E8/12 -> 29.166667 | J8: =Assumptions!E8/12 -> 29.166667 | K8: =Assumptions!E8/12 -> 29.166667 | L8: =Assumptions!E8/12 -> 29.166667 | M8: =Assumptions!E8/12 -> 29.166667 | N8: =Assumptions!E8/12 -> 29.166667 | O8: =Assumptions!E8/12 -> 29.166667 | P8: =Assumptions!E8/12 -> 29.166667 | Q8: =Assumptions!F8/12 -> 30.041667 | R8: =Assumptions!F8/12 -> 30.041667 | S8: =Assumptions!F8/12 -> 30.041667 | T8: =Assumptions!F8/12 -> 30.041667 | U8: =Assumptions!F8/12 -> 30.041667 | V8: =Assumptions!F8/12 -> 30.041667 | W8: =Assumptions!F8/12 -> 30.041667 | X8: =Assumptions!F8/12 -> 30.041667 | Y8: =Assumptions!F8/12 -> 30.041667 | Z8: =Assumptions!F8/12 -> 30.041667 | AA8: =Assumptions!F8/12 -> 30.041667 | AB8: =Assumptions!F8/12 -> 30.041667 | AC8: =Assumptions!G8/12 -> 30.942917 | AD8: =Assumptions!G8/12 -> 30.942917 | AE8: =Assumptions!G8/12 -> 30.942917 | AF8: =Assumptions!G8/12 -> 30.942917 | AG8: =Assumptions!G8/12 -> 30.942917 | AH8: =Assumptions!G8/12 -> 30.942917 | AI8: =Assumptions!G8/12 -> 30.942917 | AJ8: =Assumptions!G8/12 -> 30.942917 | AK8: =Assumptions!G8/12 -> 30.942917 | AL8: =Assumptions!G8/12 -> 30.942917 | AM8: =Assumptions!G8/12 -> 30.942917 | AN8: =Assumptions!G8/12 -> 30.942917 | AO8: =Assumptions!H8/12 -> 31.871204 | AP8: =Assumptions!H8/12 -> 31.871204 | AQ8: =Assumptions!H8/12 -> 31.871204 | AR8: =Assumptions!H8/12 -> 31.871204 | AS8: =Assumptions!H8/12 -> 31.871204 | AT8: =Assumptions!H8/12 -> 31.871204 | AU8: =Assumptions!H8/12 -> 31.871204 | AV8: =Assumptions!H8/12 -> 31.871204 | AW8: =Assumptions!H8/12 -> 31.871204 | AX8: =Assumptions!H8/12 -> 31.871204 | AY8: =Assumptions!H8/12 -> 31.871204 | AZ8: =Assumptions!H8/12 -> 31.871204 | BA8: =Assumptions!I8/12 -> 32.82734 | BB8: =Assumptions!I8/12 -> 32.82734 | BC8: =Assumptions!I8/12 -> 32.82734 | BD8: =Assumptions!I8/12 -> 32.82734 | BE8: =Assumptions!I8/12 -> 32.82734 | BF8: =Assumptions!I8/12 -> 32.82734 | BG8: =Assumptions!I8/12 -> 32.82734 | BH8: =Assumptions!I8/12 -> 32.82734 | BI8: =Assumptions!I8/12 -> 32.82734 | BJ8: =Assumptions!I8/12 -> 32.82734 | BK8: =Assumptions!I8/12 -> 32.82734 | BL8: =Assumptions!I8/12 -> 32.82734
C9: Adidas recognition reduction | E9: =SUM(Assumptions!E28:E28)*0.8/12 -> 0 | F9: =SUM(Assumptions!E28:E28)*0.8/12 -> 0 | G9: =SUM(Assumptions!E28:E28)*0.8/12 -> 0 | H9: =SUM(Assumptions!E28:E28)*0.8/12 -> 0 | I9: =SUM(Assumptions!E28:E28)*0.8/12 -> 0 | J9: =SUM(Assumptions!E28:E28)*0.8/12 -> 0 | K9: =SUM(Assumptions!E28:E28)*0.8/12 -> 0 | L9: =SUM(Assumptions!E28:E28)*0.8/12 -> 0 | M9: =SUM(Assumptions!E28:E28)*0.8/12 -> 0 | N9: =SUM(Assumptions!E28:E28)*0.8/12 -> 0 | O9: =SUM(Assumptions!E28:E28)*0.8/12 -> 0 | P9: =SUM(Assumptions!E28:E28)*0.8/12 -> 0 | Q9: =SUM(Assumptions!E28:F28)*0.8/12 -> 0.066666667 | R9: =SUM(Assumptions!E28:F28)*0.8/12 -> 0.066666667 | S9: =SUM(Assumptions!E28:F28)*0.8/12 -> 0.066666667 | T9: =SUM(Assumptions!E28:F28)*0.8/12 -> 0.066666667 | U9: =SUM(Assumptions!E28:F28)*0.8/12 -> 0.066666667 | V9: =SUM(Assumptions!E28:F28)*0.8/12 -> 0.066666667 | W9: =SUM(Assumptions!E28:F28)*0.8/12 -> 0.066666667 | X9: =SUM(Assumptions!E28:F28)*0.8/12 -> 0.066666667 | Y9: =SUM(Assumptions!E28:F28)*0.8/12 -> 0.066666667 | Z9: =SUM(Assumptions!E28:F28)*0.8/12 -> 0.066666667 | AA9: =SUM(Assumptions!E28:F28)*0.8/12 -> 0.066666667 | AB9: =SUM(Assumptions!E28:F28)*0.8/12 -> 0.066666667 | AC9: =SUM(Assumptions!E28:G28)*0.8/12 -> 0.066666667 | AD9: =SUM(Assumptions!E28:G28)*0.8/12 -> 0.066666667 | AE9: =SUM(Assumptions!E28:G28)*0.8/12 -> 0.066666667 | AF9: =SUM(Assumptions!E28:G28)*0.8/12 -> 0.066666667 | AG9: =SUM(Assumptions!E28:G28)*0.8/12 -> 0.066666667 | AH9: =SUM(Assumptions!E28:G28)*0.8/12 -> 0.066666667 | AI9: =SUM(Assumptions!E28:G28)*0.8/12 -> 0.066666667 | AJ9: =SUM(Assumptions!E28:G28)*0.8/12 -> 0.066666667 | AK9: =SUM(Assumptions!E28:G28)*0.8/12 -> 0.066666667 | AL9: =SUM(Assumptions!E28:G28)*0.8/12 -> 0.066666667 | AM9: =SUM(Assumptions!E28:G28)*0.8/12 -> 0.066666667 | AN9: =SUM(Assumptions!E28:G28)*0.8/12 -> 0.066666667 | AO9: =SUM(Assumptions!E28:H28)*0.8/12 -> 0.066666667 | AP9: =SUM(Assumptions!E28:H28)*0.8/12 -> 0.066666667 | AQ9: =SUM(Assumptions!E28:H28)*0.8/12 -> 0.066666667 | AR9: =SUM(Assumptions!E28:H28)*0.8/12 -> 0.066666667 | AS9: =SUM(Assumptions!E28:H28)*0.8/12 -> 0.066666667 | AT9: =SUM(Assumptions!E28:H28)*0.8/12 -> 0.066666667 | AU9: =SUM(Assumptions!E28:H28)*0.8/12 -> 0.066666667 | AV9: =SUM(Assumptions!E28:H28)*0.8/12 -> 0.066666667 | AW9: =SUM(Assumptions!E28:H28)*0.8/12 -> 0.066666667 | AX9: =SUM(Assumptions!E28:H28)*0.8/12 -> 0.066666667 | AY9: =SUM(Assumptions!E28:H28)*0.8/12 -> 0.066666667 | AZ9: =SUM(Assumptions!E28:H28)*0.8/12 -> 0.066666667 | BA9: =SUM(Assumptions!E28:I28)*0.8/12 -> 0.066666667 | BB9: =SUM(Assumptions!E28:I28)*0.8/12 -> 0.066666667 | BC9: =SUM(Assumptions!E28:I28)*0.8/12 -> 0.066666667 | BD9: =SUM(Assumptions!E28:I28)*0.8/12 -> 0.066666667 | BE9: =SUM(Assumptions!E28:I28)*0.8/12 -> 0.066666667 | BF9: =SUM(Assumptions!E28:I28)*0.8/12 -> 0.066666667 | BG9: =SUM(Assumptions!E28:I28)*0.8/12 -> 0.066666667 | BH9: =SUM(Assumptions!E28:I28)*0.8/12 -> 0.066666667 | BI9: =SUM(Assumptions!E28:I28)*0.8/12 -> 0.066666667 | BJ9: =SUM(Assumptions!E28:I28)*0.8/12 -> 0.066666667 | BK9: =SUM(Assumptions!E28:I28)*0.8/12 -> 0.066666667 | BL9: =SUM(Assumptions!E28:I28)*0.8/12 -> 0.066666667
C10: Commercial revenue | E10: =E8-E9 -> 29.166667 | F10: =F8-F9 -> 29.166667 | G10: =G8-G9 -> 29.166667 | H10: =H8-H9 -> 29.166667 | I10: =I8-I9 -> 29.166667 | J10: =J8-J9 -> 29.166667 | K10: =K8-K9 -> 29.166667 | L10: =L8-L9 -> 29.166667 | ... BL10: =BL8-BL9 -> 32.760674
C11: Domestic/other broadcasting | E11: =Assumptions!E13/12 -> 13.333333 | F11: =Assumptions!E13/12 -> 13.333333 | G11: =Assumptions!E13/12 -> 13.333333 | H11: =Assumptions!E13/12 -> 13.333333 | I11: =Assumptions!E13/12 -> 13.333333 | J11: =Assumptions!E13/12 -> 13.333333 | K11: =Assumptions!E13/12 -> 13.333333 | L11: =Assumptions!E13/12 -> 13.333333 | M11: =Assumptions!E13/12 -> 13.333333 | N11: =Assumptions!E13/12 -> 13.333333 | O11: =Assumptions!E13/12 -> 13.333333 | P11: =Assumptions!E13/12 -> 13.333333 | Q11: =Assumptions!F13/12 -> 13.333333 | R11: =Assumptions!F13/12 -> 13.333333 | S11: =Assumptions!F13/12 -> 13.333333 | T11: =Assumptions!F13/12 -> 13.333333 | U11: =Assumptions!F13/12 -> 13.333333 | V11: =Assumptions!F13/12 -> 13.333333 | W11: =Assumptions!F13/12 -> 13.333333 | X11: =Assumptions!F13/12 -> 13.333333 | Y11: =Assumptions!F13/12 -> 13.333333 | Z11: =Assumptions!F13/12 -> 13.333333 | AA11: =Assumptions!F13/12 -> 13.333333 | AB11: =Assumptions!F13/12 -> 13.333333 | AC11: =Assumptions!G13/12 -> 13.333333 | AD11: =Assumptions!G13/12 -> 13.333333 | AE11: =Assumptions!G13/12 -> 13.333333 | AF11: =Assumptions!G13/12 -> 13.333333 | AG11: =Assumptions!G13/12 -> 13.333333 | AH11: =Assumptions!G13/12 -> 13.333333 | AI11: =Assumptions!G13/12 -> 13.333333 | AJ11: =Assumptions!G13/12 -> 13.333333 | AK11: =Assumptions!G13/12 -> 13.333333 | AL11: =Assumptions!G13/12 -> 13.333333 | AM11: =Assumptions!G13/12 -> 13.333333 | AN11: =Assumptions!G13/12 -> 13.333333 | AO11: =Assumptions!H13/12 -> 13.333333 | AP11: =Assumptions!H13/12 -> 13.333333 | AQ11: =Assumptions!H13/12 -> 13.333333 | AR11: =Assumptions!H13/12 -> 13.333333 | AS11: =Assumptions!H13/12 -> 13.333333 | AT11: =Assumptions!H13/12 -> 13.333333 | AU11: =Assumptions!H13/12 -> 13.333333 | AV11: =Assumptions!H13/12 -> 13.333333 | AW11: =Assumptions!H13/12 -> 13.333333 | AX11: =Assumptions!H13/12 -> 13.333333 | AY11: =Assumptions!H13/12 -> 13.333333 | AZ11: =Assumptions!H13/12 -> 13.333333 | BA11: =Assumptions!I13/12 -> 13.333333 | BB11: =Assumptions!I13/12 -> 13.333333 | BC11: =Assumptions!I13/12 -> 13.333333 | BD11: =Assumptions!I13/12 -> 13.333333 | BE11: =Assumptions!I13/12 -> 13.333333 | BF11: =Assumptions!I13/12 -> 13.333333 | BG11: =Assumptions!I13/12 -> 13.333333 | BH11: =Assumptions!I13/12 -> 13.333333 | BI11: =Assumptions!I13/12 -> 13.333333 | BJ11: =Assumptions!I13/12 -> 13.333333 | BK11: =Assumptions!I13/12 -> 13.333333 | BL11: =Assumptions!I13/12 -> 13.333333
C12: European broadcasting | E12: =Assumptions!E18/12 -> 5.4166667 | F12: =Assumptions!E18/12 -> 5.4166667 | G12: =Assumptions!E18/12 -> 5.4166667 | H12: =Assumptions!E18/12 -> 5.4166667 | I12: =Assumptions!E18/12 -> 5.4166667 | J12: =Assumptions!E18/12 -> 5.4166667 | K12: =Assumptions!E18/12 -> 5.4166667 | L12: =Assumptions!E18/12 -> 5.4166667 | M12: =Assumptions!E18/12 -> 5.4166667 | N12: =Assumptions!E18/12 -> 5.4166667 | O12: =Assumptions!E18/12 -> 5.4166667 | P12: =Assumptions!E18/12 -> 5.4166667 | Q12: =Assumptions!F18/12 -> 2.9166667 | R12: =Assumptions!F18/12 -> 2.9166667 | S12: =Assumptions!F18/12 -> 2.9166667 | T12: =Assumptions!F18/12 -> 2.9166667 | U12: =Assumptions!F18/12 -> 2.9166667 | V12: =Assumptions!F18/12 -> 2.9166667 | W12: =Assumptions!F18/12 -> 2.9166667 | X12: =Assumptions!F18/12 -> 2.9166667 | Y12: =Assumptions!F18/12 -> 2.9166667 | Z12: =Assumptions!F18/12 -> 2.9166667 | AA12: =Assumptions!F18/12 -> 2.9166667 | AB12: =Assumptions!F18/12 -> 2.9166667 | AC12: =Assumptions!G18/12 -> 2.9166667 | AD12: =Assumptions!G18/12 -> 2.9166667 | AE12: =Assumptions!G18/12 -> 2.9166667 | AF12: =Assumptions!G18/12 -> 2.9166667 | AG12: =Assumptions!G18/12 -> 2.9166667 | AH12: =Assumptions!G18/12 -> 2.9166667 | AI12: =Assumptions!G18/12 -> 2.9166667 | AJ12: =Assumptions!G18/12 -> 2.9166667 | AK12: =Assumptions!G18/12 -> 2.9166667 | AL12: =Assumptions!G18/12 -> 2.9166667 | AM12: =Assumptions!G18/12 -> 2.9166667 | AN12: =Assumptions!G18/12 -> 2.9166667 | AO12: =Assumptions!H18/12 -> 2.9166667 | AP12: =Assumptions!H18/12 -> 2.9166667 | AQ12: =Assumptions!H18/12 -> 2.9166667 | AR12: =Assumptions!H18/12 -> 2.9166667 | AS12: =Assumptions!H18/12 -> 2.9166667 | AT12: =Assumptions!H18/12 -> 2.9166667 | AU12: =Assumptions!H18/12 -> 2.9166667 | AV12: =Assumptions!H18/12 -> 2.9166667 | AW12: =Assumptions!H18/12 -> 2.9166667 | AX12: =Assumptions!H18/12 -> 2.9166667 | AY12: =Assumptions!H18/12 -> 2.9166667 | AZ12: =Assumptions!H18/12 -> 2.9166667 | BA12: =Assumptions!I18/12 -> 2.9166667 | BB12: =Assumptions!I18/12 -> 2.9166667 | BC12: =Assumptions!I18/12 -> 2.9166667 | BD12: =Assumptions!I18/12 -> 2.9166667 | BE12: =Assumptions!I18/12 -> 2.9166667 | BF12: =Assumptions!I18/12 -> 2.9166667 | BG12: =Assumptions!I18/12 -> 2.9166667 | BH12: =Assumptions!I18/12 -> 2.9166667 | BI12: =Assumptions!I18/12 -> 2.9166667 | BJ12: =Assumptions!I18/12 -> 2.9166667 | BK12: =Assumptions!I18/12 -> 2.9166667 | BL12: =Assumptions!I18/12 -> 2.9166667
C13: Matchday | E13: =Assumptions!E23/12 -> 14.583333 | F13: =Assumptions!E23/12 -> 14.583333 | G13: =Assumptions!E23/12 -> 14.583333 | H13: =Assumptions!E23/12 -> 14.583333 | I13: =Assumptions!E23/12 -> 14.583333 | J13: =Assumptions!E23/12 -> 14.583333 | K13: =Assumptions!E23/12 -> 14.583333 | L13: =Assumptions!E23/12 -> 14.583333 | M13: =Assumptions!E23/12 -> 14.583333 | N13: =Assumptions!E23/12 -> 14.583333 | O13: =Assumptions!E23/12 -> 14.583333 | P13: =Assumptions!E23/12 -> 14.583333 | Q13: =Assumptions!F23/12 -> 13.333333 | R13: =Assumptions!F23/12 -> 13.333333 | S13: =Assumptions!F23/12 -> 13.333333 | T13: =Assumptions!F23/12 -> 13.333333 | U13: =Assumptions!F23/12 -> 13.333333 | V13: =Assumptions!F23/12 -> 13.333333 | W13: =Assumptions!F23/12 -> 13.333333 | X13: =Assumptions!F23/12 -> 13.333333 | Y13: =Assumptions!F23/12 -> 13.333333 | Z13: =Assumptions!F23/12 -> 13.333333 | AA13: =Assumptions!F23/12 -> 13.333333 | AB13: =Assumptions!F23/12 -> 13.333333 | AC13: =Assumptions!G23/12 -> 13.6 | AD13: =Assumptions!G23/12 -> 13.6 | AE13: =Assumptions!G23/12 -> 13.6 | AF13: =Assumptions!G23/12 -> 13.6 | AG13: =Assumptions!G23/12 -> 13.6 | AH13: =Assumptions!G23/12 -> 13.6 | AI13: =Assumptions!G23/12 -> 13.6 | AJ13: =Assumptions!G23/12 -> 13.6 | AK13: =Assumptions!G23/12 -> 13.6 | AL13: =Assumptions!G23/12 -> 13.6 | AM13: =Assumptions!G23/12 -> 13.6 | AN13: =Assumptions!G23/12 -> 13.6 | AO13: =Assumptions!H23/12 -> 13.872 | AP13: =Assumptions!H23/12 -> 13.872 | AQ13: =Assumptions!H23/12 -> 13.872 | AR13: =Assumptions!H23/12 -> 13.872 | AS13: =Assumptions!H23/12 -> 13.872 | AT13: =Assumptions!H23/12 -> 13.872 | AU13: =Assumptions!H23/12 -> 13.872 | AV13: =Assumptions!H23/12 -> 13.872 | AW13: =Assumptions!H23/12 -> 13.872 | AX13: =Assumptions!H23/12 -> 13.872 | AY13: =Assumptions!H23/12 -> 13.872 | AZ13: =Assumptions!H23/12 -> 13.872 | BA13: =Assumptions!I23/12 -> 14.14944 | BB13: =Assumptions!I23/12 -> 14.14944 | BC13: =Assumptions!I23/12 -> 14.14944 | BD13: =Assumptions!I23/12 -> 14.14944 | BE13: =Assumptions!I23/12 -> 14.14944 | BF13: =Assumptions!I23/12 -> 14.14944 | BG13: =Assumptions!I23/12 -> 14.14944 | BH13: =Assumptions!I23/12 -> 14.14944 | BI13: =Assumptions!I23/12 -> 14.14944 | BJ13: =Assumptions!I23/12 -> 14.14944 | BK13: =Assumptions!I23/12 -> 14.14944 | BL13: =Assumptions!I23/12 -> 14.14944
C14: Total revenue | E14: =SUM(E10:E13) -> 62.5 | F14: =SUM(F10:F13) -> 62.5 | G14: =SUM(G10:G13) -> 62.5 | H14: =SUM(H10:H13) -> 62.5 | I14: =SUM(I10:I13) -> 62.5 | J14: =SUM(J10:J13) -> 62.5 | K14: =SUM(K10:K13) -> 62.5 | L14: =SUM(L10:L13) -> 62.5 | ... BL14: =SUM(BL10:BL13) -> 63.160114
C16: Inherited group payroll | E16: =Assumptions!E38/12 -> 29.166667 | F16: =E16 -> 29.166667 | G16: =F16 -> 29.166667 | H16: =G16 -> 29.166667 | I16: =H16 -> 29.166667 | J16: =I16 -> 29.166667 | K16: =J16 -> 29.166667 | L16: =K16 -> 29.166667 | M16: =L16 -> 29.166667 | ... P16: =O16 -> 29.166667 | Q16: =P16*(1+Assumptions!F43)-Assumptions!F53/12 -> 28.083333 | R16: =Q16 -> 28.083333 | S16: =R16 -> 28.083333 | T16: =S16 -> 28.083333 | U16: =T16 -> 28.083333 | V16: =U16 -> 28.083333 | W16: =V16 -> 28.083333 | X16: =W16 -> 28.083333 | Y16: =X16 -> 28.083333 | ... AB16: =AA16 -> 28.083333 | AC16: =AB16*(1+Assumptions!G43)-Assumptions!G53/12 -> 27.395 | AD16: =AC16 -> 27.395 | AE16: =AD16 -> 27.395 | AF16: =AE16 -> 27.395 | AG16: =AF16 -> 27.395 | AH16: =AG16 -> 27.395 | AI16: =AH16 -> 27.395 | AJ16: =AI16 -> 27.395 | AK16: =AJ16 -> 27.395 | ... AN16: =AM16 -> 27.395 | AO16: =AN16*(1+Assumptions!H43)-Assumptions!H53/12 -> 27.109567 | AP16: =AO16 -> 27.109567 | AQ16: =AP16 -> 27.109567 | AR16: =AQ16 -> 27.109567 | AS16: =AR16 -> 27.109567 | AT16: =AS16 -> 27.109567 | AU16: =AT16 -> 27.109567 | AV16: =AU16 -> 27.109567 | AW16: =AV16 -> 27.109567 | ... AZ16: =AY16 -> 27.109567 | BA16: =AZ16*(1+Assumptions!I43)-Assumptions!I53/12 -> 27.235091 | BB16: =BA16 -> 27.235091 | BC16: =BB16 -> 27.235091 | BD16: =BC16 -> 27.235091 | BE16: =BD16 -> 27.235091 | BF16: =BE16 -> 27.235091 | BG16: =BF16 -> 27.235091 | BH16: =BG16 -> 27.235091 | BI16: =BH16 -> 27.235091 | ... BL16: =BK16 -> 27.235091
C17: Relevant retained squad payroll | E17: =E16*IF(Capacity!$E$9<0,Assumptions!E48,Capacity!$E$9) -> 21.875 | F17: =F16*IF(Capacity!$E$9<0,Assumptions!E48,Capacity!$E$9) -> 21.875 | G17: =G16*IF(Capacity!$E$9<0,Assumptions!E48,Capacity!$E$9) -> 21.875 | H17: =H16*IF(Capacity!$E$9<0,Assumptions!E48,Capacity!$E$9) -> 21.875 | I17: =I16*IF(Capacity!$E$9<0,Assumptions!E48,Capacity!$E$9) -> 21.875 | J17: =J16*IF(Capacity!$E$9<0,Assumptions!E48,Capacity!$E$9) -> 21.875 | K17: =K16*IF(Capacity!$E$9<0,Assumptions!E48,Capacity!$E$9) -> 21.875 | L17: =L16*IF(Capacity!$E$9<0,Assumptions!E48,Capacity!$E$9) -> 21.875 | M17: =M16*IF(Capacity!$E$9<0,Assumptions!E48,Capacity!$E$9) -> 21.875 | N17: =N16*IF(Capacity!$E$9<0,Assumptions!E48,Capacity!$E$9) -> 21.875 | O17: =O16*IF(Capacity!$E$9<0,Assumptions!E48,Capacity!$E$9) -> 21.875 | P17: =P16*IF(Capacity!$E$9<0,Assumptions!E48,Capacity!$E$9) -> 21.875 | Q17: =Q16*IF(Capacity!$E$9<0,Assumptions!F48,Capacity!$E$9) -> 21.0625 | R17: =R16*IF(Capacity!$E$9<0,Assumptions!F48,Capacity!$E$9) -> 21.0625 | S17: =S16*IF(Capacity!$E$9<0,Assumptions!F48,Capacity!$E$9) -> 21.0625 | T17: =T16*IF(Capacity!$E$9<0,Assumptions!F48,Capacity!$E$9) -> 21.0625 | U17: =U16*IF(Capacity!$E$9<0,Assumptions!F48,Capacity!$E$9) -> 21.0625 | V17: =V16*IF(Capacity!$E$9<0,Assumptions!F48,Capacity!$E$9) -> 21.0625 | W17: =W16*IF(Capacity!$E$9<0,Assumptions!F48,Capacity!$E$9) -> 21.0625 | X17: =X16*IF(Capacity!$E$9<0,Assumptions!F48,Capacity!$E$9) -> 21.0625 | Y17: =Y16*IF(Capacity!$E$9<0,Assumptions!F48,Capacity!$E$9) -> 21.0625 | Z17: =Z16*IF(Capacity!$E$9<0,Assumptions!F48,Capacity!$E$9) -> 21.0625 | AA17: =AA16*IF(Capacity!$E$9<0,Assumptions!F48,Capacity!$E$9) -> 21.0625 | AB17: =AB16*IF(Capacity!$E$9<0,Assumptions!F48,Capacity!$E$9) -> 21.0625 | AC17: =AC16*IF(Capacity!$E$9<0,Assumptions!G48,Capacity!$E$9) -> 20.54625 | AD17: =AD16*IF(Capacity!$E$9<0,Assumptions!G48,Capacity!$E$9) -> 20.54625 | AE17: =AE16*IF(Capacity!$E$9<0,Assumptions!G48,Capacity!$E$9) -> 20.54625 | AF17: =AF16*IF(Capacity!$E$9<0,Assumptions!G48,Capacity!$E$9) -> 20.54625 | AG17: =AG16*IF(Capacity!$E$9<0,Assumptions!G48,Capacity!$E$9) -> 20.54625 | AH17: =AH16*IF(Capacity!$E$9<0,Assumptions!G48,Capacity!$E$9) -> 20.54625 | AI17: =AI16*IF(Capacity!$E$9<0,Assumptions!G48,Capacity!$E$9) -> 20.54625 | AJ17: =AJ16*IF(Capacity!$E$9<0,Assumptions!G48,Capacity!$E$9) -> 20.54625 | AK17: =AK16*IF(Capacity!$E$9<0,Assumptions!G48,Capacity!$E$9) -> 20.54625 | AL17: =AL16*IF(Capacity!$E$9<0,Assumptions!G48,Capacity!$E$9) -> 20.54625 | AM17: =AM16*IF(Capacity!$E$9<0,Assumptions!G48,Capacity!$E$9) -> 20.54625 | AN17: =AN16*IF(Capacity!$E$9<0,Assumptions!G48,Capacity!$E$9) -> 20.54625 | AO17: =AO16*IF(Capacity!$E$9<0,Assumptions!H48,Capacity!$E$9) -> 20.332175 | AP17: =AP16*IF(Capacity!$E$9<0,Assumptions!H48,Capacity!$E$9) -> 20.332175 | AQ17: =AQ16*IF(Capacity!$E$9<0,Assumptions!H48,Capacity!$E$9) -> 20.332175 | AR17: =AR16*IF(Capacity!$E$9<0,Assumptions!H48,Capacity!$E$9) -> 20.332175 | AS17: =AS16*IF(Capacity!$E$9<0,Assumptions!H48,Capacity!$E$9) -> 20.332175 | AT17: =AT16*IF(Capacity!$E$9<0,Assumptions!H48,Capacity!$E$9) -> 20.332175 | AU17: =AU16*IF(Capacity!$E$9<0,Assumptions!H48,Capacity!$E$9) -> 20.332175 | AV17: =AV16*IF(Capacity!$E$9<0,Assumptions!H48,Capacity!$E$9) -> 20.332175 | AW17: =AW16*IF(Capacity!$E$9<0,Assumptions!H48,Capacity!$E$9) -> 20.332175 | AX17: =AX16*IF(Capacity!$E$9<0,Assumptions!H48,Capacity!$E$9) -> 20.332175 | AY17: =AY16*IF(Capacity!$E$9<0,Assumptions!H48,Capacity!$E$9) -> 20.332175 | AZ17: =AZ16*IF(Capacity!$E$9<0,Assumptions!H48,Capacity!$E$9) -> 20.332175 | BA17: =BA16*IF(Capacity!$E$9<0,Assumptions!I48,Capacity!$E$9) -> 20.426319 | BB17: =BB16*IF(Capacity!$E$9<0,Assumptions!I48,Capacity!$E$9) -> 20.426319 | BC17: =BC16*IF(Capacity!$E$9<0,Assumptions!I48,Capacity!$E$9) -> 20.426319 | BD17: =BD16*IF(Capacity!$E$9<0,Assumptions!I48,Capacity!$E$9) -> 20.426319 | BE17: =BE16*IF(Capacity!$E$9<0,Assumptions!I48,Capacity!$E$9) -> 20.426319 | BF17: =BF16*IF(Capacity!$E$9<0,Assumptions!I48,Capacity!$E$9) -> 20.426319 | BG17: =BG16*IF(Capacity!$E$9<0,Assumptions!I48,Capacity!$E$9) -> 20.426319 | BH17: =BH16*IF(Capacity!$E$9<0,Assumptions!I48,Capacity!$E$9) -> 20.426319 | BI17: =BI16*IF(Capacity!$E$9<0,Assumptions!I48,Capacity!$E$9) -> 20.426319 | BJ17: =BJ16*IF(Capacity!$E$9<0,Assumptions!I48,Capacity!$E$9) -> 20.426319 | BK17: =BK16*IF(Capacity!$E$9<0,Assumptions!I48,Capacity!$E$9) -> 20.426319 | BL17: =BL16*IF(Capacity!$E$9<0,Assumptions!I48,Capacity!$E$9) -> 20.426319
C18: New cohort all-in payroll | E18: =0 -> 0 | F18: =0 -> 0 | G18: =0 -> 0 | H18: =0 -> 0 | I18: =0 -> 0 | J18: =0 -> 0 | K18: =IF(0<Assumptions!E83*12,Capacity!$E$7/12,0) -> 0 | L18: =IF(1<Assumptions!E83*12,Capacity!$E$7/12,0) -> 0 | M18: =IF(2<Assumptions!E83*12,Capacity!$E$7/12,0) -> 0 | N18: =IF(3<Assumptions!E83*12,Capacity!$E$7/12,0) -> 0 | O18: =IF(4<Assumptions!E83*12,Capacity!$E$7/12,0) -> 0 | P18: =IF(5<Assumptions!E83*12,Capacity!$E$7/12,0) -> 0 | Q18: =IF(6<Assumptions!E83*12,Capacity!$E$7/12,0)+IF(0<Assumptions!F83*12,Assumptions!F68/12,0) -> 1 | R18: =IF(7<Assumptions!E83*12,Capacity!$E$7/12,0)+IF(1<Assumptions!F83*12,Assumptions!F68/12,0) -> 1 | S18: =IF(8<Assumptions!E83*12,Capacity!$E$7/12,0)+IF(2<Assumptions!F83*12,Assumptions!F68/12,0) -> 1 | T18: =IF(9<Assumptions!E83*12,Capacity!$E$7/12,0)+IF(3<Assumptions!F83*12,Assumptions!F68/12,0) -> 1 | U18: =IF(10<Assumptions!E83*12,Capacity!$E$7/12,0)+IF(4<Assumptions!F83*12,Assumptions!F68/12,0) -> 1 | V18: =IF(11<Assumptions!E83*12,Capacity!$E$7/12,0)+IF(5<Assumptions!F83*12,Assumptions!F68/12,0) -> 1 | W18: =IF(12<Assumptions!E83*12,Capacity!$E$7/12,0)+IF(6<Assumptions!F83*12,Assumptions!F68/12,0) -> 1 | X18: =IF(13<Assumptions!E83*12,Capacity!$E$7/12,0)+IF(7<Assumptions!F83*12,Assumptions!F68/12,0) -> 1 | Y18: =IF(14<Assumptions!E83*12,Capacity!$E$7/12,0)+IF(8<Assumptions!F83*12,Assumptions!F68/12,0) -> 1 | Z18: =IF(15<Assumptions!E83*12,Capacity!$E$7/12,0)+IF(9<Assumptions!F83*12,Assumptions!F68/12,0) -> 1 | AA18: =IF(16<Assumptions!E83*12,Capacity!$E$7/12,0)+IF(10<Assumptions!F83*12,Assumptions!F68/12,0) -> 1 | AB18: =IF(17<Assumptions!E83*12,Capacity!$E$7/12,0)+IF(11<Assumptions!F83*12,Assumptions!F68/12,0) -> 1 | AC18: =IF(18<Assumptions!E83*12,Capacity!$E$7/12,0)+IF(12<Assumptions!F83*12,Assumptions!F68/12,0)+IF(0<Assumptions!G83*12,Assumptions!G68/12,0) -> 2 | AD18: =IF(19<Assumptions!E83*12,Capacity!$E$7/12,0)+IF(13<Assumptions!F83*12,Assumptions!F68/12,0)+IF(1<Assumptions!G83*12,Assumptions!G68/12,0) -> 2 | AE18: =IF(20<Assumptions!E83*12,Capacity!$E$7/12,0)+IF(14<Assumptions!F83*12,Assumptions!F68/12,0)+IF(2<Assumptions!G83*12,Assumptions!G68/12,0) -> 2 | AF18: =IF(21<Assumptions!E83*12,Capacity!$E$7/12,0)+IF(15<Assumptions!F83*12,Assumptions!F68/12,0)+IF(3<Assumptions!G83*12,Assumptions!G68/12,0) -> 2 | AG18: =IF(22<Assumptions!E83*12,Capacity!$E$7/12,0)+IF(16<Assumptions!F83*12,Assumptions!F68/12,0)+IF(4<Assumptions!G83*12,Assumptions!G68/12,0) -> 2 | AH18: =IF(23<Assumptions!E83*12,Capacity!$E$7/12,0)+IF(17<Assumptions!F83*12,Assumptions!F68/12,0)+IF(5<Assumptions!G83*12,Assumptions!G68/12,0) -> 2 | AI18: =IF(24<Assumptions!E83*12,Capacity!$E$7/12,0)+IF(18<Assumptions!F83*12,Assumptions!F68/12,0)+IF(6<Assumptions!G83*12,Assumptions!G68/12,0) -> 2 | AJ18: =IF(25<Assumptions!E83*12,Capacity!$E$7/12,0)+IF(19<Assumptions!F83*12,Assumptions!F68/12,0)+IF(7<Assumptions!G83*12,Assumptions!G68/12,0) -> 2 | AK18: =IF(26<Assumptions!E83*12,Capacity!$E$7/12,0)+IF(20<Assumptions!F83*12,Assumptions!F68/12,0)+IF(8<Assumptions!G83*12,Assumptions!G68/12,0) -> 2 | AL18: =IF(27<Assumptions!E83*12,Capacity!$E$7/12,0)+IF(21<Assumptions!F83*12,Assumptions!F68/12,0)+IF(9<Assumptions!G83*12,Assumptions!G68/12,0) -> 2 | AM18: =IF(28<Assumptions!E83*12,Capacity!$E$7/12,0)+IF(22<Assumptions!F83*12,Assumptions!F68/12,0)+IF(10<Assumptions!G83*12,Assumptions!G68/12,0) -> 2 | AN18: =IF(29<Assumptions!E83*12,Capacity!$E$7/12,0)+IF(23<Assumptions!F83*12,Assumptions!F68/12,0)+IF(11<Assumptions!G83*12,Assumptions!G68/12,0) -> 2 | AO18: =IF(30<Assumptions!E83*12,Capacity!$E$7/12,0)+IF(24<Assumptions!F83*12,Assumptions!F68/12,0)+IF(12<Assumptions!G83*12,Assumptions!G68/12,0)+IF(0<Assumptions!H83*12,Assumptions!H68/12,0) -> 3 | AP18: =IF(31<Assumptions!E83*12,Capacity!$E$7/12,0)+IF(25<Assumptions!F83*12,Assumptions!F68/12,0)+IF(13<Assumptions!G83*12,Assumptions!G68/12,0)+IF(1<Assumptions!H83*12,Assumptions!H68/12,0) -> 3 | AQ18: =IF(32<Assumptions!E83*12,Capacity!$E$7/12,0)+IF(26<Assumptions!F83*12,Assumptions!F68/12,0)+IF(14<Assumptions!G83*12,Assumptions!G68/12,0)+IF(2<Assumptions!H83*12,Assumptions!H68/12,0) -> 3 | AR18: =IF(33<Assumptions!E83*12,Capacity!$E$7/12,0)+IF(27<Assumptions!F83*12,Assumptions!F68/12,0)+IF(15<Assumptions!G83*12,Assumptions!G68/12,0)+IF(3<Assumptions!H83*12,Assumptions!H68/12,0) -> 3 | AS18: =IF(34<Assumptions!E83*12,Capacity!$E$7/12,0)+IF(28<Assumptions!F83*12,Assumptions!F68/12,0)+IF(16<Assumptions!G83*12,Assumptions!G68/12,0)+IF(4<Assumptions!H83*12,Assumptions!H68/12,0) -> 3 | AT18: =IF(35<Assumptions!E83*12,Capacity!$E$7/12,0)+IF(29<Assumptions!F83*12,Assumptions!F68/12,0)+IF(17<Assumptions!G83*12,Assumptions!G68/12,0)+IF(5<Assumptions!H83*12,Assumptions!H68/12,0) -> 3 | AU18: =IF(36<Assumptions!E83*12,Capacity!$E$7/12,0)+IF(30<Assumptions!F83*12,Assumptions!F68/12,0)+IF(18<Assumptions!G83*12,Assumptions!G68/12,0)+IF(6<Assumptions!H83*12,Assumptions!H68/12,0) -> 3 | AV18: =IF(37<Assumptions!E83*12,Capacity!$E$7/12,0)+IF(31<Assumptions!F83*12,Assumptions!F68/12,0)+IF(19<Assumptions!G83*12,Assumptions!G68/12,0)+IF(7<Assumptions!H83*12,Assumptions!H68/12,0) -> 3 | AW18: =IF(38<Assumptions!E83*12,Capacity!$E$7/12,0)+IF(32<Assumptions!F83*12,Assumptions!F68/12,0)+IF(20<Assumptions!G83*12,Assumptions!G68/12,0)+IF(8<Assumptions!H83*12,Assumptions!H68/12,0) -> 3 | AX18: =IF(39<Assumptions!E83*12,Capacity!$E$7/12,0)+IF(33<Assumptions!F83*12,Assumptions!F68/12,0)+IF(21<Assumptions!G83*12,Assumptions!G68/12,0)+IF(9<Assumptions!H83*12,Assumptions!H68/12,0) -> 3 | AY18: =IF(40<Assumptions!E83*12,Capacity!$E$7/12,0)+IF(34<Assumptions!F83*12,Assumptions!F68/12,0)+IF(22<Assumptions!G83*12,Assumptions!G68/12,0)+IF(10<Assumptions!H83*12,Assumptions!H68/12,0) -> 3 | AZ18: =IF(41<Assumptions!E83*12,Capacity!$E$7/12,0)+IF(35<Assumptions!F83*12,Assumptions!F68/12,0)+IF(23<Assumptions!G83*12,Assumptions!G68/12,0)+IF(11<Assumptions!H83*12,Assumptions!H68/12,0) -> 3 | BA18: =IF(42<Assumptions!E83*12,Capacity!$E$7/12,0)+IF(36<Assumptions!F83*12,Assumptions!F68/12,0)+IF(24<Assumptions!G83*12,Assumptions!G68/12,0)+IF(12<Assumptions!H83*12,Assumptions!H68/12,0)+IF(0<Assumptions!I83*12,Assumptions!I68/12,0) -> 4 | BB18: =IF(43<Assumptions!E83*12,Capacity!$E$7/12,0)+IF(37<Assumptions!F83*12,Assumptions!F68/12,0)+IF(25<Assumptions!G83*12,Assumptions!G68/12,0)+IF(13<Assumptions!H83*12,Assumptions!H68/12,0)+IF(1<Assumptions!I83*12,Assumptions!I68/12,0) -> 4 | BC18: =IF(44<Assumptions!E83*12,Capacity!$E$7/12,0)+IF(38<Assumptions!F83*12,Assumptions!F68/12,0)+IF(26<Assumptions!G83*12,Assumptions!G68/12,0)+IF(14<Assumptions!H83*12,Assumptions!H68/12,0)+IF(2<Assumptions!I83*12,Assumptions!I68/12,0) -> 4 | BD18: =IF(45<Assumptions!E83*12,Capacity!$E$7/12,0)+IF(39<Assumptions!F83*12,Assumptions!F68/12,0)+IF(27<Assumptions!G83*12,Assumptions!G68/12,0)+IF(15<Assumptions!H83*12,Assumptions!H68/12,0)+IF(3<Assumptions!I83*12,Assumptions!I68/12,0) -> 4 | BE18: =IF(46<Assumptions!E83*12,Capacity!$E$7/12,0)+IF(40<Assumptions!F83*12,Assumptions!F68/12,0)+IF(28<Assumptions!G83*12,Assumptions!G68/12,0)+IF(16<Assumptions!H83*12,Assumptions!H68/12,0)+IF(4<Assumptions!I83*12,Assumptions!I68/12,0) -> 4 | BF18: =IF(47<Assumptions!E83*12,Capacity!$E$7/12,0)+IF(41<Assumptions!F83*12,Assumptions!F68/12,0)+IF(29<Assumptions!G83*12,Assumptions!G68/12,0)+IF(17<Assumptions!H83*12,Assumptions!H68/12,0)+IF(5<Assumptions!I83*12,Assumptions!I68/12,0) -> 4 | BG18: =IF(48<Assumptions!E83*12,Capacity!$E$7/12,0)+IF(42<Assumptions!F83*12,Assumptions!F68/12,0)+IF(30<Assumptions!G83*12,Assumptions!G68/12,0)+IF(18<Assumptions!H83*12,Assumptions!H68/12,0)+IF(6<Assumptions!I83*12,Assumptions!I68/12,0) -> 4 | BH18: =IF(49<Assumptions!E83*12,Capacity!$E$7/12,0)+IF(43<Assumptions!F83*12,Assumptions!F68/12,0)+IF(31<Assumptions!G83*12,Assumptions!G68/12,0)+IF(19<Assumptions!H83*12,Assumptions!H68/12,0)+IF(7<Assumptions!I83*12,Assumptions!I68/12,0) -> 4 | BI18: =IF(50<Assumptions!E83*12,Capacity!$E$7/12,0)+IF(44<Assumptions!F83*12,Assumptions!F68/12,0)+IF(32<Assumptions!G83*12,Assumptions!G68/12,0)+IF(20<Assumptions!H83*12,Assumptions!H68/12,0)+IF(8<Assumptions!I83*12,Assumptions!I68/12,0) -> 4 | BJ18: =IF(51<Assumptions!E83*12,Capacity!$E$7/12,0)+IF(45<Assumptions!F83*12,Assumptions!F68/12,0)+IF(33<Assumptions!G83*12,Assumptions!G68/12,0)+IF(21<Assumptions!H83*12,Assumptions!H68/12,0)+IF(9<Assumptions!I83*12,Assumptions!I68/12,0) -> 4 | BK18: =IF(52<Assumptions!E83*12,Capacity!$E$7/12,0)+IF(46<Assumptions!F83*12,Assumptions!F68/12,0)+IF(34<Assumptions!G83*12,Assumptions!G68/12,0)+IF(22<Assumptions!H83*12,Assumptions!H68/12,0)+IF(10<Assumptions!I83*12,Assumptions!I68/12,0) -> 4 | BL18: =IF(53<Assumptions!E83*12,Capacity!$E$7/12,0)+IF(47<Assumptions!F83*12,Assumptions!F68/12,0)+IF(35<Assumptions!G83*12,Assumptions!G68/12,0)+IF(23<Assumptions!H83*12,Assumptions!H68/12,0)+IF(11<Assumptions!I83*12,Assumptions!I68/12,0) -> 4
C19: Total employee cost | E19: =E16+E18 -> 29.166667 | F19: =F16+F18 -> 29.166667 | G19: =G16+G18 -> 29.166667 | H19: =H16+H18 -> 29.166667 | I19: =I16+I18 -> 29.166667 | J19: =J16+J18 -> 29.166667 | K19: =K16+K18 -> 29.166667 | L19: =L16+L18 -> 29.166667 | ... BL19: =BL16+BL18 -> 31.235091
C20: Relevant actual squad payroll | E20: =E17+E18 -> 21.875 | F20: =F17+F18 -> 21.875 | G20: =G17+G18 -> 21.875 | H20: =H17+H18 -> 21.875 | I20: =I17+I18 -> 21.875 | J20: =J17+J18 -> 21.875 | K20: =K17+K18 -> 21.875 | L20: =L17+L18 -> 21.875 | ... BL20: =BL17+BL18 -> 24.426319
C21: Other operating costs | E21: =Assumptions!E58/12 -> 15.416667 | F21: =Assumptions!E58/12 -> 15.416667 | G21: =Assumptions!E58/12 -> 15.416667 | H21: =Assumptions!E58/12 -> 15.416667 | I21: =Assumptions!E58/12 -> 15.416667 | J21: =Assumptions!E58/12 -> 15.416667 | K21: =Assumptions!E58/12 -> 15.416667 | L21: =Assumptions!E58/12 -> 15.416667 | M21: =Assumptions!E58/12 -> 15.416667 | N21: =Assumptions!E58/12 -> 15.416667 | O21: =Assumptions!E58/12 -> 15.416667 | P21: =Assumptions!E58/12 -> 15.416667 | Q21: =Assumptions!F58/12 -> 15.725 | R21: =Assumptions!F58/12 -> 15.725 | S21: =Assumptions!F58/12 -> 15.725 | T21: =Assumptions!F58/12 -> 15.725 | U21: =Assumptions!F58/12 -> 15.725 | V21: =Assumptions!F58/12 -> 15.725 | W21: =Assumptions!F58/12 -> 15.725 | X21: =Assumptions!F58/12 -> 15.725 | Y21: =Assumptions!F58/12 -> 15.725 | Z21: =Assumptions!F58/12 -> 15.725 | AA21: =Assumptions!F58/12 -> 15.725 | AB21: =Assumptions!F58/12 -> 15.725 | AC21: =Assumptions!G58/12 -> 16.0395 | AD21: =Assumptions!G58/12 -> 16.0395 | AE21: =Assumptions!G58/12 -> 16.0395 | AF21: =Assumptions!G58/12 -> 16.0395 | AG21: =Assumptions!G58/12 -> 16.0395 | AH21: =Assumptions!G58/12 -> 16.0395 | AI21: =Assumptions!G58/12 -> 16.0395 | AJ21: =Assumptions!G58/12 -> 16.0395 | AK21: =Assumptions!G58/12 -> 16.0395 | AL21: =Assumptions!G58/12 -> 16.0395 | AM21: =Assumptions!G58/12 -> 16.0395 | AN21: =Assumptions!G58/12 -> 16.0395 | AO21: =Assumptions!H58/12 -> 16.36029 | AP21: =Assumptions!H58/12 -> 16.36029 | AQ21: =Assumptions!H58/12 -> 16.36029 | AR21: =Assumptions!H58/12 -> 16.36029 | AS21: =Assumptions!H58/12 -> 16.36029 | AT21: =Assumptions!H58/12 -> 16.36029 | AU21: =Assumptions!H58/12 -> 16.36029 | AV21: =Assumptions!H58/12 -> 16.36029 | AW21: =Assumptions!H58/12 -> 16.36029 | AX21: =Assumptions!H58/12 -> 16.36029 | AY21: =Assumptions!H58/12 -> 16.36029 | AZ21: =Assumptions!H58/12 -> 16.36029 | BA21: =Assumptions!I58/12 -> 16.687496 | BB21: =Assumptions!I58/12 -> 16.687496 | BC21: =Assumptions!I58/12 -> 16.687496 | BD21: =Assumptions!I58/12 -> 16.687496 | BE21: =Assumptions!I58/12 -> 16.687496 | BF21: =Assumptions!I58/12 -> 16.687496 | BG21: =Assumptions!I58/12 -> 16.687496 | BH21: =Assumptions!I58/12 -> 16.687496 | BI21: =Assumptions!I58/12 -> 16.687496 | BJ21: =Assumptions!I58/12 -> 16.687496 | BK21: =Assumptions!I58/12 -> 16.687496 | BL21: =Assumptions!I58/12 -> 16.687496
C22: EBITDA before disposal gains | E22: =E14-E19-E21 -> 17.916667 | F22: =F14-F19-F21 -> 17.916667 | G22: =G14-G19-G21 -> 17.916667 | H22: =H14-H19-H21 -> 17.916667 | I22: =I14-I19-I21 -> 17.916667 | J22: =J14-J19-J21 -> 17.916667 | K22: =K14-K19-K21 -> 17.916667 | L22: =L14-L19-L21 -> 17.916667 | ... BL22: =BL14-BL19-BL21 -> 15.237526
C24: Tangible depreciation | E24: =Assumptions!E183/12 -> 1.8333333 | F24: =Assumptions!E183/12 -> 1.8333333 | G24: =Assumptions!E183/12 -> 1.8333333 | H24: =Assumptions!E183/12 -> 1.8333333 | I24: =Assumptions!E183/12 -> 1.8333333 | J24: =Assumptions!E183/12 -> 1.8333333 | K24: =Assumptions!E183/12 -> 1.8333333 | L24: =Assumptions!E183/12 -> 1.8333333 | M24: =Assumptions!E183/12 -> 1.8333333 | N24: =Assumptions!E183/12 -> 1.8333333 | O24: =Assumptions!E183/12 -> 1.8333333 | P24: =Assumptions!E183/12 -> 1.8333333 | Q24: =Assumptions!F183/12 -> 1.8333333 | R24: =Assumptions!F183/12 -> 1.8333333 | S24: =Assumptions!F183/12 -> 1.8333333 | T24: =Assumptions!F183/12 -> 1.8333333 | U24: =Assumptions!F183/12 -> 1.8333333 | V24: =Assumptions!F183/12 -> 1.8333333 | W24: =Assumptions!F183/12 -> 1.8333333 | X24: =Assumptions!F183/12 -> 1.8333333 | Y24: =Assumptions!F183/12 -> 1.8333333 | Z24: =Assumptions!F183/12 -> 1.8333333 | AA24: =Assumptions!F183/12 -> 1.8333333 | AB24: =Assumptions!F183/12 -> 1.8333333 | AC24: =Assumptions!G183/12 -> 1.8333333 | AD24: =Assumptions!G183/12 -> 1.8333333 | AE24: =Assumptions!G183/12 -> 1.8333333 | AF24: =Assumptions!G183/12 -> 1.8333333 | AG24: =Assumptions!G183/12 -> 1.8333333 | AH24: =Assumptions!G183/12 -> 1.8333333 | AI24: =Assumptions!G183/12 -> 1.8333333 | AJ24: =Assumptions!G183/12 -> 1.8333333 | AK24: =Assumptions!G183/12 -> 1.8333333 | AL24: =Assumptions!G183/12 -> 1.8333333 | AM24: =Assumptions!G183/12 -> 1.8333333 | AN24: =Assumptions!G183/12 -> 1.8333333 | AO24: =Assumptions!H183/12 -> 1.8333333 | AP24: =Assumptions!H183/12 -> 1.8333333 | AQ24: =Assumptions!H183/12 -> 1.8333333 | AR24: =Assumptions!H183/12 -> 1.8333333 | AS24: =Assumptions!H183/12 -> 1.8333333 | AT24: =Assumptions!H183/12 -> 1.8333333 | AU24: =Assumptions!H183/12 -> 1.8333333 | AV24: =Assumptions!H183/12 -> 1.8333333 | AW24: =Assumptions!H183/12 -> 1.8333333 | AX24: =Assumptions!H183/12 -> 1.8333333 | AY24: =Assumptions!H183/12 -> 1.8333333 | AZ24: =Assumptions!H183/12 -> 1.8333333 | BA24: =Assumptions!I183/12 -> 1.8333333 | BB24: =Assumptions!I183/12 -> 1.8333333 | BC24: =Assumptions!I183/12 -> 1.8333333 | BD24: =Assumptions!I183/12 -> 1.8333333 | BE24: =Assumptions!I183/12 -> 1.8333333 | BF24: =Assumptions!I183/12 -> 1.8333333 | BG24: =Assumptions!I183/12 -> 1.8333333 | BH24: =Assumptions!I183/12 -> 1.8333333 | BI24: =Assumptions!I183/12 -> 1.8333333 | BJ24: =Assumptions!I183/12 -> 1.8333333 | BK24: =Assumptions!I183/12 -> 1.8333333 | BL24: =Assumptions!I183/12 -> 1.8333333
